Workbook

Sheet Konfiguracja
A1: KONFIGURACJA — LISTA STAD I DOSTAWCÓW
A2: Nr | B2: Nazwa stada | C2: Linia genetyczna | D2: Data wstawienia | E2: Kury wstawione | G2: LISTA WYBORU (auto)
A3: 1 | B3: ='Dzienne 1'!C1 -> Ferma za Lakiem K1 | C3: ='Dzienne 1'!C2 -> Ross 308 | D3: ='Dzienne 1'!C3 -> 45870 | E3: ='Dzienne 1'!C4 -> 10352 | G3: =Konfiguracja!B3 -> Ferma za Lakiem K1
A4: 2 | B4: ='Dzienne 2'!C1 -> Ferma za Lakiem K2 | C4: ='Dzienne 2'!C2 -> Ross 308 | D4: ='Dzienne 2'!C3 -> 45870 | E4: ='Dzienne 2'!C4 -> 10352 | G4: =Konfiguracja!B4 -> Ferma za Lakiem K2
A5: 3 | B5: ='Dzienne 3'!C1 -> Ferma za Lakiem K3 | C5: ='Dzienne 3'!C2 -> Ross 308 | D5: ='Dzienne 3'!C3 -> 45870 | E5: ='Dzienne 3'!C4 -> 10352 | G5: =Konfiguracja!B5 -> Ferma za Lakiem K3
A6: 4 | B6: ='Dzienne 4'!C1 -> Ferma za Lakiem K4 | C6: ='Dzienne 4'!C2 -> Ross 308 | D6: ='Dzienne 4'!C3 -> 45870 | E6: ='Dzienne 4'!C4 -> 10364 | G6: =Konfiguracja!B6 -> Ferma za Lakiem K4
A7: 5 | B7: ='Dzienne 5'!C1 -> W1 | C7: ='Dzienne 5'!C2 -> Ross 308 | D7: ='Dzienne 5'!C3 -> 46070 | E7: ='Dzienne 5'!C4 -> 10964 | G7: =Konfiguracja!B7 -> W1
A8: 6 | B8: ='Dzienne 6'!C1 -> W2 | C8: ='Dzienne 6'!C2 -> Ross308 | D8: ='Dzienne 6'!C3 -> 22.06. | E8: ='Dzienne 6'!C4 -> 10996 | G8: =Konfiguracja!B8 -> W2
A9: 7 | B9: ='Dzienne 7'!C1 -> w3 | C9: ='Dzienne 7'!C2 -> Ross 308 | D9: ='Dzienne 7'!C3 -> 46070 | E9: ='Dzienne 7'!C4 -> 10019 | G9: =Konfiguracja!B9 -> w3
A10: 8 | B10: ='Dzienne 8'!C1 -> W4 | C10: ='Dzienne 8'!C2 -> Ross 308 | D10: ='Dzienne 8'!C3 -> 46070 | E10: ='Dzienne 8'!C4 -> 10996 | G10: =Konfiguracja!B10 -> W4
A11: 9 | B11: ='Dzienne 9'!C1 -> 0 | C11: ='Dzienne 9'!C2 -> 0 | D11: ='Dzienne 9'!C3 -> 0 | E11: ='Dzienne 9'!C4 -> 0 | G11: =Konfiguracja!B11 -> 0
A12: 10 | B12: ='Dzienne 10'!C1 -> 0 | C12: ='Dzienne 10'!C2 -> 0 | D12: ='Dzienne 10'!C3 -> 0 | E12: ='Dzienne 10'!C4 -> 0 | G12: =Konfiguracja!B12 -> 0
A13: 11 | B13: ='Dzienne 11'!C1 -> 0 | C13: ='Dzienne 11'!C2 -> 0 | D13: ='Dzienne 11'!C3 -> 0 | E13: ='Dzienne 11'!C4 -> 0 | G13: =Konfiguracja!B13 -> 0
A14: 12 | B14: ='Dzienne 12'!C1 -> 0 | C14: ='Dzienne 12'!C2 -> 0 | D14: ='Dzienne 12'!C3 -> 0 | E14: ='Dzienne 12'!C4 -> 0 | G14: =Konfiguracja!B14 -> 0
G15: =Konfiguracja!B18 -> Kujawski Wiktor 12.03.2025 stare
A16: DOSTAWCY ZEWNĘTRZNI | G16: =Konfiguracja!B19 -> Kujawski Wiktor 24.07.2025 śred
A17: Nr | B17: Nazwa dostawcy | G17: =Konfiguracja!B20 -> Kujawski Wiktor 04.12.2025 młode
A18: 1 | B18: Kujawski Wiktor 12.03.2025 stare | G18: =Konfiguracja!B21 -> Merchel
A19: 2 | B19: Kujawski Wiktor 24.07.2025 śred | G19: =Konfiguracja!B22 -> Ferma za Laskiem ściółka
A20: 3 | B20: Kujawski Wiktor 04.12.2025 młode | G20: =Konfiguracja!B23 -> Urbaś Cobb+
A21: 4 | B21: Merchel | G21: =Konfiguracja!B24 -> 0
A22: 5 | B22: Ferma za Laskiem ściółka | G22: =Konfiguracja!B25 -> 0
A23: 6 | B23: Urbaś Cobb+ | G23: =Konfiguracja!B26 -> 0
A24: 7 | G24: =Konfiguracja!B27 -> 0
A25: 8 | G25: =Konfiguracja!B28 -> 0
A26: 9 | G26: =Konfiguracja!B29 -> 0
A27: 10 | G27: =Konfiguracja!B30 -> 0
A28: 11 | G28: =Konfiguracja!B31 -> 0
A29: 12 | G29: =Konfiguracja!B32 -> 0
A30: 13 | G30: =Konfiguracja!B33 -> 0
A31: 14 | G31: =Konfiguracja!B34 -> 0
A32: 15 | G32: =Konfiguracja!B35 -> 0
A33: 16 | G33: =Konfiguracja!B36 -> 0
A34: 17 | G34: =Konfiguracja!B37 -> 0
A35: 18 | G35: =Konfiguracja!B38 -> 0
... A54: 37 | G54: =Konfiguracja!B57 -> 0
A55: 38
A56: 39
A57: 40
A59: Stada (12) = liczba kurników. Dostawcy zewn.: 40 miejsc (6 stałych + dorywczy). Lista wyboru pobiera stada + dostawców automatycznie.

Sheet Dzienne 1
A1: Nazwa stada: | C1: Ferma za Lakiem K1
A2: Linia genetyczna: | C2: Ross 308
A3: Data wstawienia: | C3: 45870
A4: Kury wstawione: | C4: 10352 | E4: Koguty wstawione: | G4: 1102 | H4: Wiek wstaw. (tyg): | I4: 0
A6: Data | B6: Tyg.życia | C6: Kury żywe | D6: Koguty żywe | E6: Upadki kury | F6: Upadki koguty | G6: Upadki %kum. | H6: Jaja ogółem | I6: Jaja wylęg. | J6: % jaj wylęg. | K6: % nieśności | L6: Waga jaja(g) | M6: Pasza kury(kg) | N6: Pasza kog.(kg) | O6: Dawka kura(g) | P6: Dawka kog.(g) | Q6: Woda(l) | R6: Woda:Pasza | S6: Temp.kurnik°C | T6: Temp.magaz.jaj°C | U6: Waga kury(g) | V6: Waga kog.(g) | W6: Suplement./Leczenie | X6: Notatki wet.
A7: 46178 | B7: =IF(A7="","",IFERROR(INT((A7-C3)/7)+I4,"")) -> 44 | C7: 9764 | D7: 766 | F7: 2 | G7: =IF(A7="","",IFERROR(SUM(E$7:E7)/C4*100,"")) -> 0 | H7: 6640 | I7: 6481 | J7: =IF(OR(A7="",H7="",H7=0),"",I7/H7*100) -> 97.605422 | K7: =IF(OR(A7="",C7="",C7=0),"",H7/C7*100) -> 68.004916 | L7: 65.7 | M7: 1689 | N7: 86 | O7: =IF(OR(A7="",C7="",C7=0),"",M7/C7*1000) -> 172.98238 | P7: =IF(OR(A7="",D7="",D7=0),"",N7/D7*1000) -> 112.27154 | Q7: 3453 | R7: =IF(OR(A7="",M7="",M7+N7=0),"",Q7/(M7+N7)) -> 1.9453521
A8: 46179 | B8: =IF(A8="","",IFERROR(INT((A8-C3)/7)+I4,"")) -> 44 | C8: 9760 | D8: 763 | E8: 4 | F8: 3 | G8: =IF(A8="","",IFERROR(SUM(E$7:E8)/C4*100,"")) -> 0.038639876 | H8: 6838 | I8: 6698 | J8: =IF(OR(A8="",H8="",H8=0),"",I8/H8*100) -> 97.952618 | K8: =IF(OR(A8="",C8="",C8=0),"",H8/C8*100) -> 70.061475 | L8: 65.6 | M8: 1689 | N8: 86 | O8: =IF(OR(A8="",C8="",C8=0),"",M8/C8*1000) -> 173.05328 | P8: =IF(OR(A8="",D8="",D8=0),"",N8/D8*1000) -> 112.71298 | Q8: 3367 | R8: =IF(OR(A8="",M8="",M8+N8=0),"",Q8/(M8+N8)) -> 1.8969014
A9: 46180 | B9: =IF(A9="","",IFERROR(INT((A9-C3)/7)+I4,"")) -> 44 | C9: 9758 | D9: 763 | E9: 2 | G9: =IF(A9="","",IFERROR(SUM(E$7:E9)/C4*100,"")) -> 0.057959815 | H9: 6783 | I9: 6625 | J9: =IF(OR(A9="",H9="",H9=0),"",I9/H9*100) -> 97.670647 | K9: =IF(OR(A9="",C9="",C9=0),"",H9/C9*100) -> 69.512195 | L9: 65.5 | M9: 1688 | N9: 86 | O9: =IF(OR(A9="",C9="",C9=0),"",M9/C9*1000) -> 172.98627 | P9: =IF(OR(A9="",D9="",D9=0),"",N9/D9*1000) -> 112.71298 | Q9: 3370 | R9: =IF(OR(A9="",M9="",M9+N9=0),"",Q9/(M9+N9)) -> 1.8996618
A10: 46181 | B10: =IF(A10="","",IFERROR(INT((A10-C3)/7)+I4,"")) -> 44 | C10: 9753 | D10: 761 | E10: 5 | F10: 2 | G10: =IF(A10="","",IFERROR(SUM(E$7:E10)/C4*100,"")) -> 0.10625966 | H10: 6843 | I10: 6664 | J10: =IF(OR(A10="",H10="",H10=0),"",I10/H10*100) -> 97.384188 | K10: =IF(OR(A10="",C10="",C10=0),"",H10/C10*100) -> 70.163027 | L10: 65.5 | M10: 1687 | N10: 86 | O10: =IF(OR(A10="",C10="",C10=0),"",M10/C10*1000) -> 172.97242 | P10: =IF(OR(A10="",D10="",D10=0),"",N10/D10*1000) -> 113.0092 | Q10: 3264 | R10: =IF(OR(A10="",M10="",M10+N10=0),"",Q10/(M10+N10)) -> 1.8409475
A11: 46182 | B11: =IF(A11="","",IFERROR(INT((A11-C3)/7)+I4,"")) -> 44 | C11: 9750 | D11: 760 | E11: 3 | F11: 1 | G11: =IF(A11="","",IFERROR(SUM(E$7:E11)/C4*100,"")) -> 0.13523957 | H11: 6726 | I11: 6513 | J11: =IF(OR(A11="",H11="",H11=0),"",I11/H11*100) -> 96.833185 | K11: =IF(OR(A11="",C11="",C11=0),"",H11/C11*100) -> 68.984615 | L11: 65.5 | M11: 1687 | N11: 86 | O11: =IF(OR(A11="",C11="",C11=0),"",M11/C11*1000) -> 173.02564 | P11: =IF(OR(A11="",D11="",D11=0),"",N11/D11*1000) -> 113.15789 | Q11: 3409 | R11: =IF(OR(A11="",M11="",M11+N11=0),"",Q11/(M11+N11)) -> 1.9227298
A12: 46183 | B12: =IF(A12="","",IFERROR(INT((A12-C3)/7)+I4,"")) -> 44 | C12: 9747 | D12: 734 | E12: 3 | F12: 26 | G12: =IF(A12="","",IFERROR(SUM(E$7:E12)/C4*100,"")) -> 0.16421947 | H12: 6863 | I12: 6686 | J12: =IF(OR(A12="",H12="",H12=0),"",I12/H12*100) -> 97.420953 | K12: =IF(OR(A12="",C12="",C12=0),"",H12/C12*100) -> 70.411409 | L12: 65.5 | M12: 1687 | N12: 86 | O12: =IF(OR(A12="",C12="",C12=0),"",M12/C12*1000) -> 173.0789 | P12: =IF(OR(A12="",D12="",D12=0),"",N12/D12*1000) -> 117.16621 | Q12: 3340 | R12: =IF(OR(A12="",M12="",M12+N12=0),"",Q12/(M12+N12)) -> 1.8838127 | W12: AviD3 1l + Avimin 1l+ Avihepasilimerin 2l (W CIĄGŁYM PIVIU DAWKA NA 1000LITRÓW WODY)
A13: 46184 | B13: =IF(A13="","",IFERROR(INT((A13-C3)/7)+I4,"")) -> 44 | C13: 9746 | D13: 733 | E13: 1 | F13: 1 | G13: =IF(A13="","",IFERROR(SUM(E$7:E13)/C4*100,"")) -> 0.17387944 | H13: 6803 | I13: 6670 | J13: =IF(OR(A13="",H13="",H13=0),"",I13/H13*100) -> 98.04498 | K13: =IF(OR(A13="",C13="",C13=0),"",H13/C13*100) -> 69.802996 | L13: 65.5 | M13: 1687 | N13: 86 | O13: =IF(OR(A13="",C13="",C13=0),"",M13/C13*1000) -> 173.09666 | P13: =IF(OR(A13="",D13="",D13=0),"",N13/D13*1000) -> 117.32606 | Q13: 3155 | R13: =IF(OR(A13="",M13="",M13+N13=0),"",Q13/(M13+N13)) -> 1.7794698 | U13: 3889 | V13: 4572 | W13: AviD3 1l + Avimin 1l+ Avihepasilimerin 2l (W CIĄGŁYM PIVIU DAWKA NA 1000LITRÓW WODY)
A14: 46185 | B14: =IF(A14="","",IFERROR(INT((A14-C3)/7)+I4,"")) -> 45 | C14: 9744 | D14: 733 | E14: 2 | G14: =IF(A14="","",IFERROR(SUM(E$7:E14)/C4*100,"")) -> 0.19319938 | H14: 6595 | I14: 6454 | J14: =IF(OR(A14="",H14="",H14=0),"",I14/H14*100) -> 97.862017 | K14: =IF(OR(A14="",C14="",C14=0),"",H14/C14*100) -> 67.682677 | L14: 65.7 | M14: 1686 | N14: 82 | O14: =IF(OR(A14="",C14="",C14=0),"",M14/C14*1000) -> 173.02956 | P14: =IF(OR(A14="",D14="",D14=0),"",N14/D14*1000) -> 111.86903 | Q14: 3331 | R14: =IF(OR(A14="",M14="",M14+N14=0),"",Q14/(M14+N14)) -> 1.8840498 | W14: AviD3 1l + Avimin 1l+ Avihepasilimerin 2l (W CIĄGŁYM PIVIU DAWKA NA 1000LITRÓW WODY)
A15: 46186 | B15: =IF(A15="","",IFERROR(INT((A15-C3)/7)+I4,"")) -> 45 | C15: 9743 | D15: 731 | E15: 1 | F15: 2 | G15: =IF(A15="","",IFERROR(SUM(E$7:E15)/C4*100,"")) -> 0.20285935 | H15: 6527 | I15: 6376 | J15: =IF(OR(A15="",H15="",H15=0),"",I15/H15*100) -> 97.686533 | K15: =IF(OR(A15="",C15="",C15=0),"",H15/C15*100) -> 66.991686 | L15: 65.8 | M15: 1686 | N15: 82 | O15: =IF(OR(A15="",C15="",C15=0),"",M15/C15*1000) -> 173.04732 | P15: =IF(OR(A15="",D15="",D15=0),"",N15/D15*1000) -> 112.1751 | Q15: 3330 | R15: =IF(OR(A15="",M15="",M15+N15=0),"",Q15/(M15+N15)) -> 1.8834842 | W15: AviD3 1l + Avimin 1l+ Avihepasilimerin 2l (W CIĄGŁYM PIVIU DAWKA NA 1000LITRÓW WODY)
A16: 46187 | B16: =IF(A16="","",IFERROR(INT((A16-C3)/7)+I4,"")) -> 45 | C16: 9742 | D16: 731 | E16: 1 | G16: =IF(A16="","",IFERROR(SUM(E$7:E16)/C4*100,"")) -> 0.21251932 | H16: 6687 | I16: 6508 | J16: =IF(OR(A16="",H16="",H16=0),"",I16/H16*100) -> 97.323164 | K16: =IF(OR(A16="",C16="",C16=0),"",H16/C16*100) -> 68.640936 | L16: 66 | M16: 1686 | N16: 82 | O16: =IF(OR(A16="",C16="",C16=0),"",M16/C16*1000) -> 173.06508 | P16: =IF(OR(A16="",D16="",D16=0),"",N16/D16*1000) -> 112.1751 | Q16: 3148 | R16: =IF(OR(A16="",M16="",M16+N16=0),"",Q16/(M16+N16)) -> 1.780543 | W16: AviD3 1l + Avimin 1l+ Avihepasilimerin 2l (W CIĄGŁYM PIVIU DAWKA NA 1000LITRÓW WODY)
A17: 46188 | B17: =IF(A17="","",IFERROR(INT((A17-C3)/7)+I4,"")) -> 45 | C17: 9736 | D17: 727 | E17: 6 | F17: 4 | G17: =IF(A17="","",IFERROR(SUM(E$7:E17)/C4*100,"")) -> 0.27047913 | H17: 6728 | I17: 6572 | J17: =IF(OR(A17="",H17="",H17=0),"",I17/H17*100) -> 97.681332 | K17: =IF(OR(A17="",C17="",C17=0),"",H17/C17*100) -> 69.104355 | L17: 65.8 | M17: 1686 | N17: 82 | O17: =IF(OR(A17="",C17="",C17=0),"",M17/C17*1000) -> 173.17173 | P17: =IF(OR(A17="",D17="",D17=0),"",N17/D17*1000) -> 112.7923 | Q17: 3244 | R17: =IF(OR(A17="",M17="",M17+N17=0),"",Q17/(M17+N17)) -> 1.8348416
A18: 46189 | B18: =IF(A18="","",IFERROR(INT((A18-C3)/7)+I4,"")) -> 45 | C18: 9731 | D18: 727 | E18: 5 | G18: =IF(A18="","",IFERROR(SUM(E$7:E18)/C4*100,"")) -> 0.31877898 | H18: 6689 | I18: 6546 | J18: =IF(OR(A18="",H18="",H18=0),"",I18/H18*100) -> 97.862162 | K18: =IF(OR(A18="",C18="",C18=0),"",H18/C18*100) -> 68.739081 | L18: 65.8 | M18: 1684 | N18: 82 | O18: =IF(OR(A18="",C18="",C18=0),"",M18/C18*1000) -> 173.05518 | P18: =IF(OR(A18="",D18="",D18=0),"",N18/D18*1000) -> 112.7923 | Q18: 3273 | R18: =IF(OR(A18="",M18="",M18+N18=0),"",Q18/(M18+N18)) -> 1.8533409
A19: 46190 | B19: =IF(A19="","",IFERROR(INT((A19-C3)/7)+I4,"")) -> 45 | C19: 9731 | D19: 726 | F19: 1 | G19: =IF(A19="","",IFERROR(SUM(E$7:E19)/C4*100,"")) -> 0.31877898 | H19: 6700 | I19: 6559 | J19: =IF(OR(A19="",H19="",H19=0),"",I19/H19*100) -> 97.895522 | K19: =IF(OR(A19="",C19="",C19=0),"",H19/C19*100) -> 68.852122 | L19: 65.7 | M19: 1684 | N19: 82 | O19: =IF(OR(A19="",C19="",C19=0),"",M19/C19*1000) -> 173.05518 | P19: =IF(OR(A19="",D19="",D19=0),"",N19/D19*1000) -> 112.94766 | Q19: 3443 | R19: =IF(OR(A19="",M19="",M19+N19=0),"",Q19/(M19+N19)) -> 1.9496036
A20: 46191 | B20: =IF(A20="","",IFERROR(INT((A20-C3)/7)+I4,"")) -> 45 | C20: 9727 | D20: 725 | E20: 4 | F20: 1 | G20: =IF(A20="","",IFERROR(SUM(E$7:E20)/C4*100,"")) -> 0.35741886 | H20: 6597 | I20: 6467 | J20: =IF(OR(A20="",H20="",H20=0),"",I20/H20*100) -> 98.029407 | K20: =IF(OR(A20="",C20="",C20=0),"",H20/C20*100) -> 67.821528 | L20: 65.9 | M20: 1684 | N20: 82 | O20: =IF(OR(A20="",C20="",C20=0),"",M20/C20*1000) -> 173.12635 | P20: =IF(OR(A20="",D20="",D20=0),"",N20/D20*1000) -> 113.10345 | Q20: 3413 | R20: =IF(OR(A20="",M20="",M20+N20=0),"",Q20/(M20+N20)) -> 1.9326161 | U20: 3986 | V20: 4614
A21: 46192 | B21: =IF(A21="","",IFERROR(INT((A21-C3)/7)+I4,"")) -> 46 | C21: 9725 | D21: 725 | E21: 2 | G21: =IF(A21="","",IFERROR(SUM(E$7:E21)/C4*100,"")) -> 0.37673879 | H21: 6740 | I21: 6576 | J21: =IF(OR(A21="",H21="",H21=0),"",I21/H21*100) -> 97.566766 | K21: =IF(OR(A21="",C21="",C21=0),"",H21/C21*100) -> 69.305913 | L21: 65.9 | M21: 1664 | N21: 82 | O21: =IF(OR(A21="",C21="",C21=0),"",M21/C21*1000) -> 171.1054 | P21: =IF(OR(A21="",D21="",D21=0),"",N21/D21*1000) -> 113.10345 | Q21: 3521 | R21: =IF(OR(A21="",M21="",M21+N21=0),"",Q21/(M21+N21)) -> 2.0166094
A22: 46193 | B22: =IF(A22="","",IFERROR(INT((A22-C3)/7)+I4,"")) -> 46 | C22: 9724 | D22: 724 | E22: 1 | F22: 1 | G22: =IF(A22="","",IFERROR(SUM(E$7:E22)/C4*100,"")) -> 0.38639876 | H22: 6645 | I22: 6488 | J22: =IF(OR(A22="",H22="",H22=0),"",I22/H22*100) -> 97.637321 | K22: =IF(OR(A22="",C22="",C22=0),"",H22/C22*100) -> 68.336076 | L22: 65.8 | M22: 1664 | N22: 82 | O22: =IF(OR(A22="",C22="",C22=0),"",M22/C22*1000) -> 171.12299 | P22: =IF(OR(A22="",D22="",D22=0),"",N22/D22*1000) -> 113.25967 | Q22: 3506 | R22: =IF(OR(A22="",M22="",M22+N22=0),"",Q22/(M22+N22)) -> 2.0080183
A23: 46194 | B23: =IF(A23="","",IFERROR(INT((A23-C3)/7)+I4,"")) -> 46 | C23: 9717 | D23: 722 | E23: 7 | F23: 2 | G23: =IF(A23="","",IFERROR(SUM(E$7:E23)/C4*100,"")) -> 0.45401855 | H23: 6636 | I23: 6460 | J23: =IF(OR(A23="",H23="",H23=0),"",I23/H23*100) -> 97.3478 | K23: =IF(OR(A23="",C23="",C23=0),"",H23/C23*100) -> 68.292683 | L23: 65.7 | M23: 1664 | N23: 82 | O23: =IF(OR(A23="",C23="",C23=0),"",M23/C23*1000) -> 171.24627 | P23: =IF(OR(A23="",D23="",D23=0),"",N23/D23*1000) -> 113.57341 | Q23: 3312 | R23: =IF(OR(A23="",M23="",M23+N23=0),"",Q23/(M23+N23)) -> 1.8969072
A24: 46195 | B24: =IF(A24="","",IFERROR(INT((A24-C3)/7)+I4,"")) -> 46 | C24: 9712 | D24: 721 | E24: 5 | F24: 1 | G24: =IF(A24="","",IFERROR(SUM(E$7:E24)/C4*100,"")) -> 0.50231839 | H24: 6697 | I24: 6527 | J24: =IF(OR(A24="",H24="",H24=0),"",I24/H24*100) -> 97.46155 | K24: =IF(OR(A24="",C24="",C24=0),"",H24/C24*100) -> 68.955931 | L24: 65.8 | M24: 1664 | N24: 82 | O24: =IF(OR(A24="",C24="",C24=0),"",M24/C24*1000) -> 171.33443 | P24: =IF(OR(A24="",D24="",D24=0),"",N24/D24*1000) -> 113.73093 | Q24: 3470 | R24: =IF(OR(A24="",M24="",M24+N24=0),"",Q24/(M24+N24)) -> 1.9873998
A25: 46196 | B25: =IF(A25="","",IFERROR(INT((A25-C3)/7)+I4,"")) -> 46 | C25: 9711 | D25: 719 | E25: 1 | F25: 2 | G25: =IF(A25="","",IFERROR(SUM(E$7:E25)/C4*100,"")) -> 0.51197836 | H25: 5556 | I25: 5419 | J25: =IF(OR(A25="",H25="",H25=0),"",I25/H25*100) -> 97.534197 | K25: =IF(OR(A25="",C25="",C25=0),"",H25/C25*100) -> 57.213469 | L25: 66 | M25: 1664 | N25: 82 | O25: =IF(OR(A25="",C25="",C25=0),"",M25/C25*1000) -> 171.35207 | P25: =IF(OR(A25="",D25="",D25=0),"",N25/D25*1000) -> 114.04729 | Q25: 3397 | R25: =IF(OR(A25="",M25="",M25+N25=0),"",Q25/(M25+N25)) -> 1.9455899
A26: 46197 | B26: =IF(A26="","",IFERROR(INT((A26-C3)/7)+I4,"")) -> 46 | C26: 9708 | D26: 716 | E26: 3 | F26: 3 | G26: =IF(A26="","",IFERROR(SUM(E$7:E26)/C4*100,"")) -> 0.54095827 | H26: 6551 | I26: 6317 | J26: =IF(OR(A26="",H26="",H26=0),"",I26/H26*100) -> 96.428026 | K26: =IF(OR(A26="",C26="",C26=0),"",H26/C26*100) -> 67.480429 | L26: 66.2 | M26: 1664 | N26: 82 | O26: =IF(OR(A26="",C26="",C26=0),"",M26/C26*1000) -> 171.40503 | P26: =IF(OR(A26="",D26="",D26=0),"",N26/D26*1000) -> 114.52514 | Q26: 3370 | R26: =IF(OR(A26="",M26="",M26+N26=0),"",Q26/(M26+N26)) -> 1.930126
A27: 46198 | B27: =IF(A27="","",IFERROR(INT((A27-C3)/7)+I4,"")) -> 46 | C27: 9706 | D27: 716 | E27: 2 | G27: =IF(A27="","",IFERROR(SUM(E$7:E27)/C4*100,"")) -> 0.56027821 | H27: 6603 | I27: 6414 | J27: =IF(OR(A27="",H27="",H27=0),"",I27/H27*100) -> 97.137665 | K27: =IF(OR(A27="",C27="",C27=0),"",H27/C27*100) -> 68.030084 | L27: 66.2 | M27: 1664 | N27: 82 | O27: =IF(OR(A27="",C27="",C27=0),"",M27/C27*1000) -> 171.44035 | P27: =IF(OR(A27="",D27="",D27=0),"",N27/D27*1000) -> 114.52514 | Q27: 3646 | R27: =IF(OR(A27="",M27="",M27+N27=0),"",Q27/(M27+N27)) -> 2.0882016 | U27: 3905 | V27: 4687
A28: 46199 | B28: =IF(A28="","",IFERROR(INT((A28-C3)/7)+I4,"")) -> 47 | C28: 9703 | D28: 716 | E28: 3 | G28: =IF(A28="","",IFERROR(SUM(E$7:E28)/C4*100,"")) -> 0.58925811 | H28: 6644 | I28: 6466 | J28: =IF(OR(A28="",H28="",H28=0),"",I28/H28*100) -> 97.320891 | K28: =IF(OR(A28="",C28="",C28=0),"",H28/C28*100) -> 68.473668 | L28: 66.1 | M28: 1669 | N28: 80 | O28: =IF(OR(A28="",C28="",C28=0),"",M28/C28*1000) -> 172.00866 | P28: =IF(OR(A28="",D28="",D28=0),"",N28/D28*1000) -> 111.73184 | Q28: 3512 | R28: =IF(OR(A28="",M28="",M28+N28=0),"",Q28/(M28+N28)) -> 2.0080046
A29: 46200 | B29: =IF(A29="","",IFERROR(INT((A29-C3)/7)+I4,"")) -> 47 | C29: 9701 | D29: 712 | E29: 2 | F29: 4 | G29: =IF(A29="","",IFERROR(SUM(E$7:E29)/C4*100,"")) -> 0.60857805 | H29: 6564 | I29: 6390 | J29: =IF(OR(A29="",H29="",H29=0),"",I29/H29*100) -> 97.349177 | K29: =IF(OR(A29="",C29="",C29=0),"",H29/C29*100) -> 67.663128 | L29: 66.2 | M29: 1669 | N29: 80 | O29: =IF(OR(A29="",C29="",C29=0),"",M29/C29*1000) -> 172.04412 | P29: =IF(OR(A29="",D29="",D29=0),"",N29/D29*1000) -> 112.35955 | Q29: 3848 | R29: =IF(OR(A29="",M29="",M29+N29=0),"",Q29/(M29+N29)) -> 2.2001144
A30: 46201 | B30: =IF(A30="","",IFERROR(INT((A30-C3)/7)+I4,"")) -> 47 | C30: 9698 | D30: 712 | E30: 3 | G30: =IF(A30="","",IFERROR(SUM(E$7:E30)/C4*100,"")) -> 0.63755796 | H30: 6653 | I30: 6521 | J30: =IF(OR(A30="",H30="",H30=0),"",I30/H30*100) -> 98.015933 | K30: =IF(OR(A30="",C30="",C30=0),"",H30/C30*100) -> 68.601774 | L30: 66.1 | M30: 1668 | N30: 80 | O30: =IF(OR(A30="",C30="",C30=0),"",M30/C30*1000) -> 171.99423 | P30: =IF(OR(A30="",D30="",D30=0),"",N30/D30*1000) -> 112.35955 | Q30: 4006 | R30: =IF(OR(A30="",M30="",M30+N30=0),"",Q30/(M30+N30)) -> 2.291762
A31: 46202 | B31: =IF(A31="","",IFERROR(INT((A31-C3)/7)+I4,"")) -> 47 | C31: 9696 | D31: 711 | E31: 2 | F31: 1 | G31: =IF(A31="","",IFERROR(SUM(E$7:E31)/C4*100,"")) -> 0.6568779 | H31: 6428 | I31: 6303 | J31: =IF(OR(A31="",H31="",H31=0),"",I31/H31*100) -> 98.055383 | K31: =IF(OR(A31="",C31="",C31=0),"",H31/C31*100) -> 66.29538 | L31: 66.3 | M31: 1668 | N31: 80 | O31: =IF(OR(A31="",C31="",C31=0),"",M31/C31*1000) -> 172.0297 | P31: =IF(OR(A31="",D31="",D31=0),"",N31/D31*1000) -> 112.51758 | Q31: 4014 | R31: =IF(OR(A31="",M31="",M31+N31=0),"",Q31/(M31+N31)) -> 2.2963387
A32: 46203 | B32: =IF(A32="","",IFERROR(INT((A32-C3)/7)+I4,"")) -> 47 | C32: 9691 | D32: 709 | E32: 5 | F32: 2 | G32: =IF(A32="","",IFERROR(SUM(E$7:E32)/C4*100,"")) -> 0.70517774 | H32: 6411 | I32: 6293 | J32: =IF(OR(A32="",H32="",H32=0),"",I32/H32*100) -> 98.159414 | K32: =IF(OR(A32="",C32="",C32=0),"",H32/C32*100) -> 66.154164 | L32: 66.4 | M32: 1666 | N32: 80 | O32: =IF(OR(A32="",C32="",C32=0),"",M32/C32*1000) -> 171.91208 | P32: =IF(OR(A32="",D32="",D32=0),"",N32/D32*1000) -> 112.83498 | Q32: 3266 | R32: =IF(OR(A32="",M32="",M32+N32=0),"",Q32/(M32+N32)) -> 1.8705613
A33: 46204 | B33: =IF(A33="","",IFERROR(INT((A33-C3)/7)+I4,"")) -> 47 | C33: 9689 | D33: 709 | E33: 2 | F33: 0 | G33: =IF(A33="","",IFERROR(SUM(E$7:E33)/C4*100,"")) -> 0.72449768 | H33: 6374 | I33: 6222 | J33: =IF(OR(A33="",H33="",H33=0),"",I33/H33*100) -> 97.615312 | K33: =IF(OR(A33="",C33="",C33=0),"",H33/C33*100) -> 65.785943 | L33: 66.3 | M33: 1666 | N33: 80 | O33: =IF(OR(A33="",C33="",C33=0),"",M33/C33*1000) -> 171.94757 | P33: =IF(OR(A33="",D33="",D33=0),"",N33/D33*1000) -> 112.83498 | Q33: 3619 | R33: =IF(OR(A33="",M33="",M33+N33=0),"",Q33/(M33+N33)) -> 2.0727377
A34: 46205 | B34: =IF(A34="","",IFERROR(INT((A34-C3)/7)+I4,"")) -> 47 | C34: 9686 | D34: 707 | E34: 3 | F34: 2 | G34: =IF(A34="","",IFERROR(SUM(E$7:E34)/C4*100,"")) -> 0.75347759 | H34: 6389 | I34: 6200 | J34: =IF(OR(A34="",H34="",H34=0),"",I34/H34*100) -> 97.041791 | K34: =IF(OR(A34="",C34="",C34=0),"",H34/C34*100) -> 65.961181 | L34: 66.4 | M34: 1666 | N34: 80 | O34: =IF(OR(A34="",C34="",C34=0),"",M34/C34*1000) -> 172.00083 | P34: =IF(OR(A34="",D34="",D34=0),"",N34/D34*1000) -> 113.15417 | Q34: 3456 | R34: =IF(OR(A34="",M34="",M34+N34=0),"",Q34/(M34+N34)) -> 1.9793814 | U34: 3905 | V34: 4687
A35: 46206 | B35: =IF(A35="","",IFERROR(INT((A35-C3)/7)+I4,"")) -> 48 | C35: 9685 | D35: 707 | E35: 1 | F35: 1 | G35: =IF(A35="","",IFERROR(SUM(E$7:E35)/C4*100,"")) -> 0.76313756 | H35: 6548 | I35: 6369 | J35: =IF(OR(A35="",H35="",H35=0),"",I35/H35*100) -> 97.266341 | K35: =IF(OR(A35="",C35="",C35=0),"",H35/C35*100) -> 67.609706 | L35: 66.4 | M35: 1666 | N35: 80 | O35: =IF(OR(A35="",C35="",C35=0),"",M35/C35*1000) -> 172.01859 | P35: =IF(OR(A35="",D35="",D35=0),"",N35/D35*1000) -> 113.15417 | Q35: 3310 | R35: =IF(OR(A35="",M35="",M35+N35=0),"",Q35/(M35+N35)) -> 1.8957617
A36: 46207 | B36: =IF(A36="","",IFERROR(INT((A36-C3)/7)+I4,"")) -> 48 | C36: 9683 | D36: 704 | E36: 2 | F36: 2 | G36: =IF(A36="","",IFERROR(SUM(E$7:E36)/C4*100,"")) -> 0.7824575 | H36: 6316 | I36: 6155 | J36: =IF(OR(A36="",H36="",H36=0),"",I36/H36*100) -> 97.450918 | K36: =IF(OR(A36="",C36="",C36=0),"",H36/C36*100) -> 65.227719 | L36: 66.4 | M36: 1666 | N36: 82 | O36: =IF(OR(A36="",C36="",C36=0),"",M36/C36*1000) -> 172.05412 | P36: =IF(OR(A36="",D36="",D36=0),"",N36/D36*1000) -> 116.47727 | Q36: 3083 | R36: =IF(OR(A36="",M36="",M36+N36=0),"",Q36/(M36+N36)) -> 1.76373 | W36: Woxsol 2kg / 50 l wody
A37: 46208 | B37: =IF(A37="","",IFERROR(INT((A37-C3)/7)+I4,"")) -> 48 | C37: 9680 | D37: 703 | E37: 3 | F37: 1 | G37: =IF(A37="","",IFERROR(SUM(E$7:E37)/C4*100,"")) -> 0.8114374 | H37: 6462 | I37: 6309 | J37: =IF(OR(A37="",H37="",H37=0),"",I37/H37*100) -> 97.632312 | K37: =IF(OR(A37="",C37="",C37=0),"",H37/C37*100) -> 66.756198 | L37: 66.6 | M37: 1665 | N37: 82 | O37: =IF(OR(A37="",C37="",C37=0),"",M37/C37*1000) -> 172.00413 | P37: =IF(OR(A37="",D37="",D37=0),"",N37/D37*1000) -> 116.64296 | Q37: 3023 | R37: =IF(OR(A37="",M37="",M37+N37=0),"",Q37/(M37+N37)) -> 1.730395 | W37: Woxsol 2kg / 50 l wody
A38: 46209 | B38: =IF(A38="","",IFERROR(INT((A38-C3)/7)+I4,"")) -> 48 | C38: 9679 | D38: 702 | E38: 1 | F38: 1 | G38: =IF(A38="","",IFERROR(SUM(E$7:E38)/C4*100,"")) -> 0.82109737 | H38: 6379 | I38: 6231 | J38: =IF(OR(A38="",H38="",H38=0),"",I38/H38*100) -> 97.679887 | K38: =IF(OR(A38="",C38="",C38=0),"",H38/C38*100) -> 65.905569 | L38: 66.7 | M38: 1665 | N38: 82 | O38: =IF(OR(A38="",C38="",C38=0),"",M38/C38*1000) -> 172.0219 | P38: =IF(OR(A38="",D38="",D38=0),"",N38/D38*1000) -> 116.80912 | Q38: 3073 | R38: =IF(OR(A38="",M38="",M38+N38=0),"",Q38/(M38+N38)) -> 1.7590155 | W38: Woxsol 2kg / 50 l wody
A39: 46210 | B39: =IF(A39="","",IFERROR(INT((A39-C3)/7)+I4,"")) -> 48 | C39: 9677 | D39: 699 | E39: 2 | F39: 3 | G39: =IF(A39="","",IFERROR(SUM(E$7:E39)/C4*100,"")) -> 0.84041731 | H39: 6366 | I39: 6241 | J39: =IF(OR(A39="",H39="",H39=0),"",I39/H39*100) -> 98.036444 | K39: =IF(OR(A39="",C39="",C39=0),"",H39/C39*100) -> 65.784851 | L39: 66.8 | M39: 1665 | N39: 82 | O39: =IF(OR(A39="",C39="",C39=0),"",M39/C39*1000) -> 172.05746 | P39: =IF(OR(A39="",D39="",D39=0),"",N39/D39*1000) -> 117.31044 | Q39: 3065 | R39: =IF(OR(A39="",M39="",M39+N39=0),"",Q39/(M39+N39)) -> 1.7544362 | W39: Woxsol 2kg / 50 l wody
A40: 46211 | B40: =IF(A40="","",IFERROR(INT((A40-C3)/7)+I4,"")) -> 48 | C40: 9675 | D40: 698 | E40: 0 | F40: 1 | G40: =IF(A40="","",IFERROR(SUM(E$7:E40)/C4*100,"")) -> 0.84041731 | H40: 6485 | I40: 6342 | J40: =IF(OR(A40="",H40="",H40=0),"",I40/H40*100) -> 97.794911 | K40: =IF(OR(A40="",C40="",C40=0),"",H40/C40*100) -> 67.028424 | L40: 66.7 | M40: 1664 | N40: 82 | O40: =IF(OR(A40="",C40="",C40=0),"",M40/C40*1000) -> 171.98966 | P40: =IF(OR(A40="",D40="",D40=0),"",N40/D40*1000) -> 117.47851 | Q40: 2845 | R40: =IF(OR(A40="",M40="",M40+N40=0),"",Q40/(M40+N40)) -> 1.6294387 | W40: Woxsol 2kg / 50 l wody
A41: 46212 | B41: =IF(A41="","",IFERROR(INT((A41-C3)/7)+I4,"")) -> 48 | C41: =C40-E41 -> 9670 | D41: =D40-F41 -> 697 | E41: 5 | F41: 1 | G41: =IF(A41="","",IFERROR(SUM(E$7:E41)/C4*100,"")) -> 0.88871716 | H41: 6404 | I41: 6265 | J41: =IF(OR(A41="",H41="",H41=0),"",I41/H41*100) -> 97.829482 | K41: =IF(OR(A41="",C41="",C41=0),"",H41/C41*100) -> 66.22544 | L41: 66.2 | M41: 1664 | N41: 82 | O41: =IF(OR(A41="",C41="",C41=0),"",M41/C41*1000) -> 172.07859 | P41: =IF(OR(A41="",D41="",D41=0),"",N41/D41*1000) -> 117.64706 | Q41: 3070 | R41: =IF(OR(A41="",M41="",M41+N41=0),"",Q41/(M41+N41)) -> 1.7583047 | W41: Woxsol 2kg / 50 l wody
...

Sheet Dzienne 2
A1: Nazwa stada: | C1: Ferma za Lakiem K2
A2: Linia genetyczna: | C2: Ross 308
A3: Data wstawienia: | C3: 45870
A4: Kury wstawione: | C4: 10352 | E4: Koguty wstawione: | G4: 1102 | H4: Wiek wstaw. (tyg): | I4: 0
A6: Data | B6: Tyg.życia | C6: Kury żywe | D6: Koguty żywe | E6: Upadki kury | F6: Upadki koguty | G6: Upadki %kum. | H6: Jaja ogółem | I6: Jaja wylęg. | J6: % jaj wylęg. | K6: % nieśności | L6: Waga jaja(g) | M6: Pasza kury(kg) | N6: Pasza kog.(kg) | O6: Dawka kura(g) | P6: Dawka kog.(g) | Q6: Woda(l) | R6: Woda:Pasza | S6: Temp.kurnik°C | T6: Temp.magaz.jaj°C | U6: Waga kury(g) | V6: Waga kog.(g) | W6: Suplement./Leczenie | X6: Notatki wet.
A7: 46178 | B7: =IF(A7="","",IFERROR(INT((A7-C3)/7)+I4,"")) -> 44 | C7: 9999 | D7: 866 | E7: 1 | G7: =IF(A7="","",IFERROR(SUM(E$7:E7)/C4*100,"")) -> 0.0096599691 | H7: 7076 | I7: 6955 | J7: =IF(OR(A7="",H7="",H7=0),"",I7/H7*100) -> 98.289994 | K7: =IF(OR(A7="",C7="",C7=0),"",H7/C7*100) -> 70.767077 | L7: 66.3 | M7: 1630 | N7: 82 | O7: =IF(OR(A7="",C7="",C7=0),"",M7/C7*1000) -> 163.0163 | P7: =IF(OR(A7="",D7="",D7=0),"",N7/D7*1000) -> 94.688222 | Q7: 3576 | R7: =IF(OR(A7="",M7="",M7+N7=0),"",Q7/(M7+N7)) -> 2.088785
A8: 46179 | B8: =IF(A8="","",IFERROR(INT((A8-C3)/7)+I4,"")) -> 44 | C8: 9994 | D8: 863 | E8: 5 | F8: 3 | G8: =IF(A8="","",IFERROR(SUM(E$7:E8)/C4*100,"")) -> 0.057959815 | H8: 7050 | I8: 6875 | J8: =IF(OR(A8="",H8="",H8=0),"",I8/H8*100) -> 97.51773 | K8: =IF(OR(A8="",C8="",C8=0),"",H8/C8*100) -> 70.542325 | L8: 66.4 | M8: 1630 | N8: 82 | O8: =IF(OR(A8="",C8="",C8=0),"",M8/C8*1000) -> 163.09786 | P8: =IF(OR(A8="",D8="",D8=0),"",N8/D8*1000) -> 95.017381 | Q8: 3492 | R8: =IF(OR(A8="",M8="",M8+N8=0),"",Q8/(M8+N8)) -> 2.0397196
A9: 46180 | B9: =IF(A9="","",IFERROR(INT((A9-C3)/7)+I4,"")) -> 44 | C9: 9988 | D9: 860 | E9: 6 | F9: 3 | G9: =IF(A9="","",IFERROR(SUM(E$7:E9)/C4*100,"")) -> 0.11591963 | H9: 6976 | I9: 6787 | J9: =IF(OR(A9="",H9="",H9=0),"",I9/H9*100) -> 97.290711 | K9: =IF(OR(A9="",C9="",C9=0),"",H9/C9*100) -> 69.843813 | L9: 66.4 | M9: 1629 | N9: 82 | O9: =IF(OR(A9="",C9="",C9=0),"",M9/C9*1000) -> 163.09571 | P9: =IF(OR(A9="",D9="",D9=0),"",N9/D9*1000) -> 95.348837 | Q9: 3395 | R9: =IF(OR(A9="",M9="",M9+N9=0),"",Q9/(M9+N9)) -> 1.9842198
A10: 46181 | B10: =IF(A10="","",IFERROR(INT((A10-C3)/7)+I4,"")) -> 44 | C10: 9985 | D10: 858 | E10: 3 | F10: 2 | G10: =IF(A10="","",IFERROR(SUM(E$7:E10)/C4*100,"")) -> 0.14489954 | H10: 7050 | I10: 6927 | J10: =IF(OR(A10="",H10="",H10=0),"",I10/H10*100) -> 98.255319 | K10: =IF(OR(A10="",C10="",C10=0),"",H10/C10*100) -> 70.605909 | L10: 66.4 | M10: 1628 | N10: 82 | O10: =IF(OR(A10="",C10="",C10=0),"",M10/C10*1000) -> 163.04457 | P10: =IF(OR(A10="",D10="",D10=0),"",N10/D10*1000) -> 95.571096 | Q10: 3464 | R10: =IF(OR(A10="",M10="",M10+N10=0),"",Q10/(M10+N10)) -> 2.025731
A11: 46182 | B11: =IF(A11="","",IFERROR(INT((A11-C3)/7)+I4,"")) -> 44 | C11: 9983 | D11: 857 | E11: 2 | F11: 1 | G11: =IF(A11="","",IFERROR(SUM(E$7:E11)/C4*100,"")) -> 0.16421947 | H11: 7052 | I11: 6915 | J11: =IF(OR(A11="",H11="",H11=0),"",I11/H11*100) -> 98.057289 | K11: =IF(OR(A11="",C11="",C11=0),"",H11/C11*100) -> 70.640088 | L11: 66.3 | M11: 1628 | N11: 82 | O11: =IF(OR(A11="",C11="",C11=0),"",M11/C11*1000) -> 163.07723 | P11: =IF(OR(A11="",D11="",D11=0),"",N11/D11*1000) -> 95.682614 | Q11: 3690 | R11: =IF(OR(A11="",M11="",M11+N11=0),"",Q11/(M11+N11)) -> 2.1578947
A12: 46183 | B12: =IF(A12="","",IFERROR(INT((A12-C3)/7)+I4,"")) -> 44 | C12: 9976 | D12: 828 | E12: 7 | F12: 29 | G12: =IF(A12="","",IFERROR(SUM(E$7:E12)/C4*100,"")) -> 0.23183926 | H12: 7021 | I12: 6908 | J12: =IF(OR(A12="",H12="",H12=0),"",I12/H12*100) -> 98.390543 | K12: =IF(OR(A12="",C12="",C12=0),"",H12/C12*100) -> 70.378909 | L12: 66.3 | M12: 1628 | N12: 82 | O12: =IF(OR(A12="",C12="",C12=0),"",M12/C12*1000) -> 163.19166 | P12: =IF(OR(A12="",D12="",D12=0),"",N12/D12*1000) -> 99.033816 | Q12: 3504 | R12: =IF(OR(A12="",M12="",M12+N12=0),"",Q12/(M12+N12)) -> 2.0491228 | W12: AviD3 1l + Avimin 1l+ Avihepasilimerin 2l (W CIĄGŁYM PIVIU DAWKA NA 1000LITRÓW WODY)
A13: 46184 | B13: =IF(A13="","",IFERROR(INT((A13-C3)/7)+I4,"")) -> 44 | C13: 9976 | D13: 827 | F13: 1 | G13: =IF(A13="","",IFERROR(SUM(E$7:E13)/C4*100,"")) -> 0.23183926 | H13: 6940 | I13: 6800 | J13: =IF(OR(A13="",H13="",H13=0),"",I13/H13*100) -> 97.982709 | K13: =IF(OR(A13="",C13="",C13=0),"",H13/C13*100) -> 69.566961 | L13: 66.5 | M13: 1628 | N13: 82 | O13: =IF(OR(A13="",C13="",C13=0),"",M13/C13*1000) -> 163.19166 | P13: =IF(OR(A13="",D13="",D13=0),"",N13/D13*1000) -> 99.153567 | Q13: 3284 | R13: =IF(OR(A13="",M13="",M13+N13=0),"",Q13/(M13+N13)) -> 1.9204678 | U13: 4185 | V13: 4585 | W13: AviD3 1l + Avimin 1l+ Avihepasilimerin 2l (W CIĄGŁYM PIVIU DAWKA NA 1000LITRÓW WODY)
A14: 46185 | B14: =IF(A14="","",IFERROR(INT((A14-C3)/7)+I4,"")) -> 45 | C14: 9974 | D14: 827 | E14: 2 | G14: =IF(A14="","",IFERROR(SUM(E$7:E14)/C4*100,"")) -> 0.2511592 | H14: 6900 | I14: 6760 | J14: =IF(OR(A14="",H14="",H14=0),"",I14/H14*100) -> 97.971014 | K14: =IF(OR(A14="",C14="",C14=0),"",H14/C14*100) -> 69.179868 | L14: 66.6 | M14: 1626 | N14: 78 | O14: =IF(OR(A14="",C14="",C14=0),"",M14/C14*1000) -> 163.02386 | P14: =IF(OR(A14="",D14="",D14=0),"",N14/D14*1000) -> 94.316808 | Q14: 3467 | R14: =IF(OR(A14="",M14="",M14+N14=0),"",Q14/(M14+N14)) -> 2.0346244 | W14: AviD3 1l + Avimin 1l+ Avihepasilimerin 2l (W CIĄGŁYM PIVIU DAWKA NA 1000LITRÓW WODY)
A15: 46186 | B15: =IF(A15="","",IFERROR(INT((A15-C3)/7)+I4,"")) -> 45 | C15: 9969 | D15: 825 | E15: 5 | F15: 2 | G15: =IF(A15="","",IFERROR(SUM(E$7:E15)/C4*100,"")) -> 0.29945904 | H15: 6820 | I15: 6676 | J15: =IF(OR(A15="",H15="",H15=0),"",I15/H15*100) -> 97.888563 | K15: =IF(OR(A15="",C15="",C15=0),"",H15/C15*100) -> 68.412077 | L15: 66.5 | M15: 1626 | N15: 78 | O15: =IF(OR(A15="",C15="",C15=0),"",M15/C15*1000) -> 163.10563 | P15: =IF(OR(A15="",D15="",D15=0),"",N15/D15*1000) -> 94.545455 | Q15: 3392 | R15: =IF(OR(A15="",M15="",M15+N15=0),"",Q15/(M15+N15)) -> 1.9906103 | W15: AviD3 1l + Avimin 1l+ Avihepasilimerin 2l (W CIĄGŁYM PIVIU DAWKA NA 1000LITRÓW WODY)
A16: 46187 | B16: =IF(A16="","",IFERROR(INT((A16-C3)/7)+I4,"")) -> 45 | C16: 9967 | D16: 825 | E16: 2 | G16: =IF(A16="","",IFERROR(SUM(E$7:E16)/C4*100,"")) -> 0.31877898 | H16: 7007 | I16: 6853 | J16: =IF(OR(A16="",H16="",H16=0),"",I16/H16*100) -> 97.802198 | K16: =IF(OR(A16="",C16="",C16=0),"",H16/C16*100) -> 70.301997 | L16: 66.7 | M16: 1626 | N16: 78 | O16: =IF(OR(A16="",C16="",C16=0),"",M16/C16*1000) -> 163.13836 | P16: =IF(OR(A16="",D16="",D16=0),"",N16/D16*1000) -> 94.545455 | Q16: 3278 | R16: =IF(OR(A16="",M16="",M16+N16=0),"",Q16/(M16+N16)) -> 1.9237089 | W16: AviD3 1l + Avimin 1l+ Avihepasilimerin 2l (W CIĄGŁYM PIVIU DAWKA NA 1000LITRÓW WODY)
A17: 46188 | B17: =IF(A17="","",IFERROR(INT((A17-C3)/7)+I4,"")) -> 45 | C17: 9965 | D17: 825 | E17: 2 | G17: =IF(A17="","",IFERROR(SUM(E$7:E17)/C4*100,"")) -> 0.33809892 | H17: 6921 | I17: 6785 | J17: =IF(OR(A17="",H17="",H17=0),"",I17/H17*100) -> 98.034966 | K17: =IF(OR(A17="",C17="",C17=0),"",H17/C17*100) -> 69.453086 | L17: 66.6 | M17: 1626 | N17: 78 | O17: =IF(OR(A17="",C17="",C17=0),"",M17/C17*1000) -> 163.1711 | P17: =IF(OR(A17="",D17="",D17=0),"",N17/D17*1000) -> 94.545455 | Q17: 3390 | R17: =IF(OR(A17="",M17="",M17+N17=0),"",Q17/(M17+N17)) -> 1.9894366
A18: 46189 | B18: =IF(A18="","",IFERROR(INT((A18-C3)/7)+I4,"")) -> 45 | C18: 9959 | D18: 822 | E18: 6 | F18: 3 | G18: =IF(A18="","",IFERROR(SUM(E$7:E18)/C4*100,"")) -> 0.39605873 | H18: 6890 | I18: 6751 | J18: =IF(OR(A18="",H18="",H18=0),"",I18/H18*100) -> 97.982583 | K18: =IF(OR(A18="",C18="",C18=0),"",H18/C18*100) -> 69.183653 | L18: 66.5 | M18: 1626 | N18: 78 | O18: =IF(OR(A18="",C18="",C18=0),"",M18/C18*1000) -> 163.2694 | P18: =IF(OR(A18="",D18="",D18=0),"",N18/D18*1000) -> 94.890511 | Q18: 3476 | R18: =IF(OR(A18="",M18="",M18+N18=0),"",Q18/(M18+N18)) -> 2.0399061
A19: 46190 | B19: =IF(A19="","",IFERROR(INT((A19-C3)/7)+I4,"")) -> 45 | C19: 9953 | D19: 819 | E19: 6 | F19: 3 | G19: =IF(A19="","",IFERROR(SUM(E$7:E19)/C4*100,"")) -> 0.45401855 | H19: 6834 | I19: 6689 | J19: =IF(OR(A19="",H19="",H19=0),"",I19/H19*100) -> 97.878256 | K19: =IF(OR(A19="",C19="",C19=0),"",H19/C19*100) -> 68.662715 | L19: 66.5 | M19: 1626 | N19: 78 | O19: =IF(OR(A19="",C19="",C19=0),"",M19/C19*1000) -> 163.36783 | P19: =IF(OR(A19="",D19="",D19=0),"",N19/D19*1000) -> 95.238095 | Q19: 3495 | R19: =IF(OR(A19="",M19="",M19+N19=0),"",Q19/(M19+N19)) -> 2.0510563
A20: 46191 | B20: =IF(A20="","",IFERROR(INT((A20-C3)/7)+I4,"")) -> 45 | C20: 9950 | D20: 818 | E20: 3 | F20: 1 | G20: =IF(A20="","",IFERROR(SUM(E$7:E20)/C4*100,"")) -> 0.48299845 | H20: 6839 | I20: 6685 | J20: =IF(OR(A20="",H20="",H20=0),"",I20/H20*100) -> 97.748209 | K20: =IF(OR(A20="",C20="",C20=0),"",H20/C20*100) -> 68.733668 | L20: 66.5 | M20: 1626 | N20: 78 | O20: =IF(OR(A20="",C20="",C20=0),"",M20/C20*1000) -> 163.41709 | P20: =IF(OR(A20="",D20="",D20=0),"",N20/D20*1000) -> 95.354523 | Q20: 3522 | R20: =IF(OR(A20="",M20="",M20+N20=0),"",Q20/(M20+N20)) -> 2.0669014 | U20: 4374 | V20: 4449
A21: 46192 | B21: =IF(A21="","",IFERROR(INT((A21-C3)/7)+I4,"")) -> 46 | C21: 9942 | D21: 816 | E21: 8 | F21: 2 | G21: =IF(A21="","",IFERROR(SUM(E$7:E21)/C4*100,"")) -> 0.56027821 | H21: 6869 | I21: 6720 | J21: =IF(OR(A21="",H21="",H21=0),"",I21/H21*100) -> 97.830834 | K21: =IF(OR(A21="",C21="",C21=0),"",H21/C21*100) -> 69.090726 | L21: 66.5 | M21: 1602 | N21: 86 | O21: =IF(OR(A21="",C21="",C21=0),"",M21/C21*1000) -> 161.13458 | P21: =IF(OR(A21="",D21="",D21=0),"",N21/D21*1000) -> 105.39216 | Q21: 3594 | R21: =IF(OR(A21="",M21="",M21+N21=0),"",Q21/(M21+N21)) -> 2.1291469
A22: 46193 | B22: =IF(A22="","",IFERROR(INT((A22-C3)/7)+I4,"")) -> 46 | C22: 9936 | D22: 815 | E22: 6 | F22: 1 | G22: =IF(A22="","",IFERROR(SUM(E$7:E22)/C4*100,"")) -> 0.61823802 | H22: 6725 | I22: 6569 | J22: =IF(OR(A22="",H22="",H22=0),"",I22/H22*100) -> 97.680297 | K22: =IF(OR(A22="",C22="",C22=0),"",H22/C22*100) -> 67.683172 | L22: 66.4 | M22: 1600 | N22: 86 | O22: =IF(OR(A22="",C22="",C22=0),"",M22/C22*1000) -> 161.0306 | P22: =IF(OR(A22="",D22="",D22=0),"",N22/D22*1000) -> 105.52147 | Q22: 3588 | R22: =IF(OR(A22="",M22="",M22+N22=0),"",Q22/(M22+N22)) -> 2.1281139
A23: 46194 | B23: =IF(A23="","",IFERROR(INT((A23-C3)/7)+I4,"")) -> 46 | C23: 9934 | D23: 814 | E23: 2 | F23: 1 | G23: =IF(A23="","",IFERROR(SUM(E$7:E23)/C4*100,"")) -> 0.63755796 | H23: 6834 | I23: 6719 | J23: =IF(OR(A23="",H23="",H23=0),"",I23/H23*100) -> 98.317237 | K23: =IF(OR(A23="",C23="",C23=0),"",H23/C23*100) -> 68.794041 | L23: 66.6 | M23: 1600 | N23: 86 | O23: =IF(OR(A23="",C23="",C23=0),"",M23/C23*1000) -> 161.06302 | P23: =IF(OR(A23="",D23="",D23=0),"",N23/D23*1000) -> 105.65111 | Q23: 3233 | R23: =IF(OR(A23="",M23="",M23+N23=0),"",Q23/(M23+N23)) -> 1.9175563
A24: 46195 | B24: =IF(A24="","",IFERROR(INT((A24-C3)/7)+I4,"")) -> 46 | C24: 9930 | D24: 813 | E24: 4 | F24: 1 | G24: =IF(A24="","",IFERROR(SUM(E$7:E24)/C4*100,"")) -> 0.67619784 | H24: 6887 | I24: 6750 | J24: =IF(OR(A24="",H24="",H24=0),"",I24/H24*100) -> 98.010745 | K24: =IF(OR(A24="",C24="",C24=0),"",H24/C24*100) -> 69.355488 | L24: 66.6 | M24: 1600 | N24: 105 | O24: =IF(OR(A24="",C24="",C24=0),"",M24/C24*1000) -> 161.1279 | P24: =IF(OR(A24="",D24="",D24=0),"",N24/D24*1000) -> 129.15129 | Q24: 3051 | R24: =IF(OR(A24="",M24="",M24+N24=0),"",Q24/(M24+N24)) -> 1.7894428
A25: 46196 | B25: =IF(A25="","",IFERROR(INT((A25-C3)/7)+I4,"")) -> 46 | C25: 9928 | D25: 812 | E25: 2 | F25: 1 | G25: =IF(A25="","",IFERROR(SUM(E$7:E25)/C4*100,"")) -> 0.69551777 | H25: 6706 | I25: 6528 | J25: =IF(OR(A25="",H25="",H25=0),"",I25/H25*100) -> 97.345661 | K25: =IF(OR(A25="",C25="",C25=0),"",H25/C25*100) -> 67.546334 | L25: 66.7 | M25: 1600 | N25: 105 | O25: =IF(OR(A25="",C25="",C25=0),"",M25/C25*1000) -> 161.16035 | P25: =IF(OR(A25="",D25="",D25=0),"",N25/D25*1000) -> 129.31034 | Q25: 3223 | R25: =IF(OR(A25="",M25="",M25+N25=0),"",Q25/(M25+N25)) -> 1.8903226
A26: 46197 | B26: =IF(A26="","",IFERROR(INT((A26-C3)/7)+I4,"")) -> 46 | C26: 9926 | D26: 812 | E26: 2 | G26: =IF(A26="","",IFERROR(SUM(E$7:E26)/C4*100,"")) -> 0.71483771 | H26: 6860 | I26: 6722 | J26: =IF(OR(A26="",H26="",H26=0),"",I26/H26*100) -> 97.988338 | K26: =IF(OR(A26="",C26="",C26=0),"",H26/C26*100) -> 69.111425 | L26: 66.7 | M26: 1600 | N26: 105 | O26: =IF(OR(A26="",C26="",C26=0),"",M26/C26*1000) -> 161.19283 | P26: =IF(OR(A26="",D26="",D26=0),"",N26/D26*1000) -> 129.31034 | Q26: 3469 | R26: =IF(OR(A26="",M26="",M26+N26=0),"",Q26/(M26+N26)) -> 2.0346041
A27: 46198 | B27: =IF(A27="","",IFERROR(INT((A27-C3)/7)+I4,"")) -> 46 | C27: 9923 | D27: 811 | E27: 3 | F27: 1 | G27: =IF(A27="","",IFERROR(SUM(E$7:E27)/C4*100,"")) -> 0.74381762 | H27: 6630 | I27: 6511 | J27: =IF(OR(A27="",H27="",H27=0),"",I27/H27*100) -> 98.205128 | K27: =IF(OR(A27="",C27="",C27=0),"",H27/C27*100) -> 66.814471 | L27: 66.7 | M27: 1600 | N27: 105 | O27: =IF(OR(A27="",C27="",C27=0),"",M27/C27*1000) -> 161.24156 | P27: =IF(OR(A27="",D27="",D27=0),"",N27/D27*1000) -> 129.46979 | Q27: 3803 | R27: =IF(OR(A27="",M27="",M27+N27=0),"",Q27/(M27+N27)) -> 2.2304985 | U27: 4330 | V27: 4587
A28: 46199 | B28: =IF(A28="","",IFERROR(INT((A28-C3)/7)+I4,"")) -> 47 | C28: 9921 | D28: 811 | E28: 2 | G28: =IF(A28="","",IFERROR(SUM(E$7:E28)/C4*100,"")) -> 0.76313756 | H28: 6387 | I28: 6256 | J28: =IF(OR(A28="",H28="",H28=0),"",I28/H28*100) -> 97.948959 | K28: =IF(OR(A28="",C28="",C28=0),"",H28/C28*100) -> 64.378591 | L28: 66.6 | M28: 1598 | N28: 103 | O28: =IF(OR(A28="",C28="",C28=0),"",M28/C28*1000) -> 161.07247 | P28: =IF(OR(A28="",D28="",D28=0),"",N28/D28*1000) -> 127.0037 | Q28: 3604 | R28: =IF(OR(A28="",M28="",M28+N28=0),"",Q28/(M28+N28)) -> 2.1187537 | W28: Avizotonic 2l + Respiro 0,5l / 20l wody x 2
A29: 46200 | B29: =IF(A29="","",IFERROR(INT((A29-C3)/7)+I4,"")) -> 47 | C29: 9918 | D29: 811 | E29: 3 | G29: =IF(A29="","",IFERROR(SUM(E$7:E29)/C4*100,"")) -> 0.79211747 | H29: 6569 | I29: 6458 | J29: =IF(OR(A29="",H29="",H29=0),"",I29/H29*100) -> 98.310245 | K29: =IF(OR(A29="",C29="",C29=0),"",H29/C29*100) -> 66.233112 | L29: 66.8 | M29: 1598 | N29: 103 | O29: =IF(OR(A29="",C29="",C29=0),"",M29/C29*1000) -> 161.12119 | P29: =IF(OR(A29="",D29="",D29=0),"",N29/D29*1000) -> 127.0037 | Q29: 4014 | R29: =IF(OR(A29="",M29="",M29+N29=0),"",Q29/(M29+N29)) -> 2.3597884 | W29: Avizotonic 2l + Respiro 0,5l / 20l wody x 2
A30: 46201 | B30: =IF(A30="","",IFERROR(INT((A30-C3)/7)+I4,"")) -> 47 | C30: 9917 | D30: 810 | E30: 1 | F30: 1 | G30: =IF(A30="","",IFERROR(SUM(E$7:E30)/C4*100,"")) -> 0.80177743 | H30: 6684 | I30: 6574 | J30: =IF(OR(A30="",H30="",H30=0),"",I30/H30*100) -> 98.354279 | K30: =IF(OR(A30="",C30="",C30=0),"",H30/C30*100) -> 67.399415 | L30: 66.8 | M30: 1598 | N30: 103 | O30: =IF(OR(A30="",C30="",C30=0),"",M30/C30*1000) -> 161.13744 | P30: =IF(OR(A30="",D30="",D30=0),"",N30/D30*1000) -> 127.16049 | Q30: 4098 | R30: =IF(OR(A30="",M30="",M30+N30=0),"",Q30/(M30+N30)) -> 2.4091711 | W30: Avizotonic 2l + Respiro 0,5l / 20l wody x 2
A31: 46202 | B31: =IF(A31="","",IFERROR(INT((A31-C3)/7)+I4,"")) -> 47 | C31: 9902 | D31: 805 | E31: 15 | F31: 5 | G31: =IF(A31="","",IFERROR(SUM(E$7:E31)/C4*100,"")) -> 0.94667697 | H31: 6371 | I31: 6238 | J31: =IF(OR(A31="",H31="",H31=0),"",I31/H31*100) -> 97.912416 | K31: =IF(OR(A31="",C31="",C31=0),"",H31/C31*100) -> 64.340537 | L31: 67 | M31: 1594 | N31: 103 | O31: =IF(OR(A31="",C31="",C31=0),"",M31/C31*1000) -> 160.97758 | P31: =IF(OR(A31="",D31="",D31=0),"",N31/D31*1000) -> 127.95031 | Q31: 4201 | R31: =IF(OR(A31="",M31="",M31+N31=0),"",Q31/(M31+N31)) -> 2.4755451 | W31: Avizotonic 2l + Respiro 0,5l / 20l wody x 2
A32: 46203 | B32: =IF(A32="","",IFERROR(INT((A32-C3)/7)+I4,"")) -> 47 | C32: 9896 | D32: 803 | E32: 6 | F32: 2 | G32: =IF(A32="","",IFERROR(SUM(E$7:E32)/C4*100,"")) -> 1.0046368 | H32: 6123 | I32: 6009 | J32: =IF(OR(A32="",H32="",H32=0),"",I32/H32*100) -> 98.138168 | K32: =IF(OR(A32="",C32="",C32=0),"",H32/C32*100) -> 61.873484 | L32: 67 | M32: 1594 | N32: 103 | O32: =IF(OR(A32="",C32="",C32=0),"",M32/C32*1000) -> 161.07518 | P32: =IF(OR(A32="",D32="",D32=0),"",N32/D32*1000) -> 128.26899 | Q32: 3410 | R32: =IF(OR(A32="",M32="",M32+N32=0),"",Q32/(M32+N32)) -> 2.0094284 | W32: Avizotonic 2l + Respiro 0,5l / 20l wody x 2
A33: 46204 | B33: =IF(A33="","",IFERROR(INT((A33-C3)/7)+I4,"")) -> 47 | C33: 9887 | D33: 800 | E33: 9 | F33: 3 | G33: =IF(A33="","",IFERROR(SUM(E$7:E33)/C4*100,"")) -> 1.0915765 | H33: 6045 | I33: 5881 | J33: =IF(OR(A33="",H33="",H33=0),"",I33/H33*100) -> 97.287014 | K33: =IF(OR(A33="",C33="",C33=0),"",H33/C33*100) -> 61.140892 | L33: 67 | M33: 1594 | N33: 103 | O33: =IF(OR(A33="",C33="",C33=0),"",M33/C33*1000) -> 161.22181 | P33: =IF(OR(A33="",D33="",D33=0),"",N33/D33*1000) -> 128.75 | Q33: 2614 | R33: =IF(OR(A33="",M33="",M33+N33=0),"",Q33/(M33+N33)) -> 1.5403654
A34: 46205 | B34: =IF(A34="","",IFERROR(INT((A34-C3)/7)+I4,"")) -> 47 | C34: 9877 | D34: 796 | E34: 10 | F34: 4 | G34: =IF(A34="","",IFERROR(SUM(E$7:E34)/C4*100,"")) -> 1.1881762 | H34: 6318 | I34: 6158 | J34: =IF(OR(A34="",H34="",H34=0),"",I34/H34*100) -> 97.467553 | K34: =IF(OR(A34="",C34="",C34=0),"",H34/C34*100) -> 63.966792 | L34: 63.9 | M34: 1591 | N34: 82 | O34: =IF(OR(A34="",C34="",C34=0),"",M34/C34*1000) -> 161.0813 | P34: =IF(OR(A34="",D34="",D34=0),"",N34/D34*1000) -> 103.01508 | Q34: 3615 | R34: =IF(OR(A34="",M34="",M34+N34=0),"",Q34/(M34+N34)) -> 2.160789
A35: 46206 | B35: =IF(A35="","",IFERROR(INT((A35-C3)/7)+I4,"")) -> 48 | C35: 9875 | D35: 765 | E35: 2 | F35: 1 | G35: =IF(A35="","",IFERROR(SUM(E$7:E35)/C4*100,"")) -> 1.2074961 | H35: 6505 | I35: 6325 | J35: =IF(OR(A35="",H35="",H35=0),"",I35/H35*100) -> 97.232898 | K35: =IF(OR(A35="",C35="",C35=0),"",H35/C35*100) -> 65.873418 | L35: 65.8 | M35: 1590 | N35: 82 | O35: =IF(OR(A35="",C35="",C35=0),"",M35/C35*1000) -> 161.01266 | P35: =IF(OR(A35="",D35="",D35=0),"",N35/D35*1000) -> 107.18954 | Q35: 3321 | R35: =IF(OR(A35="",M35="",M35+N35=0),"",Q35/(M35+N35)) -> 1.986244
A36: 46207 | B36: =IF(A36="","",IFERROR(INT((A36-C3)/7)+I4,"")) -> 48 | C36: 9872 | D36: 795 | E36: 3 | F36: 0 | G36: =IF(A36="","",IFERROR(SUM(E$7:E36)/C4*100,"")) -> 1.236476 | H36: 6584 | I36: 6431 | J36: =IF(OR(A36="",H36="",H36=0),"",I36/H36*100) -> 97.676185 | K36: =IF(OR(A36="",C36="",C36=0),"",H36/C36*100) -> 66.693679 | L36: 66.6 | M36: 1590 | N36: 84 | O36: =IF(OR(A36="",C36="",C36=0),"",M36/C36*1000) -> 161.06159 | P36: =IF(OR(A36="",D36="",D36=0),"",N36/D36*1000) -> 105.66038 | Q36: 3016 | R36: =IF(OR(A36="",M36="",M36+N36=0),"",Q36/(M36+N36)) -> 1.8016726 | W36: Woxsol 2kg / 50 l wody
A37: 46208 | B37: =IF(A37="","",IFERROR(INT((A37-C3)/7)+I4,"")) -> 48 | C37: 9865 | D37: 795 | E37: 7 | F37: 1 | G37: =IF(A37="","",IFERROR(SUM(E$7:E37)/C4*100,"")) -> 1.3040958 | H37: 6512 | I37: 6341 | J37: =IF(OR(A37="",H37="",H37=0),"",I37/H37*100) -> 97.374079 | K37: =IF(OR(A37="",C37="",C37=0),"",H37/C37*100) -> 66.011151 | L37: 65.9 | M37: 1589 | N37: 84 | O37: =IF(OR(A37="",C37="",C37=0),"",M37/C37*1000) -> 161.07451 | P37: =IF(OR(A37="",D37="",D37=0),"",N37/D37*1000) -> 105.66038 | Q37: 3082 | R37: =IF(OR(A37="",M37="",M37+N37=0),"",Q37/(M37+N37)) -> 1.8421996 | W37: Woxsol 2kg / 50 l wody
A38: 46209 | B38: =IF(A38="","",IFERROR(INT((A38-C3)/7)+I4,"")) -> 48 | C38: 9862 | D38: 794 | E38: 3 | F38: 0 | G38: =IF(A38="","",IFERROR(SUM(E$7:E38)/C4*100,"")) -> 1.3330757 | H38: 6625 | I38: 6489 | J38: =IF(OR(A38="",H38="",H38=0),"",I38/H38*100) -> 97.94717 | K38: =IF(OR(A38="",C38="",C38=0),"",H38/C38*100) -> 67.177043 | L38: 67.1 | M38: 1588 | N38: 84 | O38: =IF(OR(A38="",C38="",C38=0),"",M38/C38*1000) -> 161.02211 | P38: =IF(OR(A38="",D38="",D38=0),"",N38/D38*1000) -> 105.79345 | Q38: 3071 | R38: =IF(OR(A38="",M38="",M38+N38=0),"",Q38/(M38+N38)) -> 1.8367225 | W38: Woxsol 2kg / 50 l wody
A39: 46210 | B39: =IF(A39="","",IFERROR(INT((A39-C3)/7)+I4,"")) -> 48 | C39: 9860 | D39: 794 | E39: 2 | F39: 0 | G39: =IF(A39="","",IFERROR(SUM(E$7:E39)/C4*100,"")) -> 1.3523957 | H39: 6491 | I39: 6276 | J39: =IF(OR(A39="",H39="",H39=0),"",I39/H39*100) -> 96.687721 | K39: =IF(OR(A39="",C39="",C39=0),"",H39/C39*100) -> 65.831643 | L39: 65.8 | M39: 1588 | N39: 84 | O39: =IF(OR(A39="",C39="",C39=0),"",M39/C39*1000) -> 161.05477 | P39: =IF(OR(A39="",D39="",D39=0),"",N39/D39*1000) -> 105.79345 | Q39: 3072 | R39: =IF(OR(A39="",M39="",M39+N39=0),"",Q39/(M39+N39)) -> 1.8373206 | W39: Woxsol 2kg / 50 l wody
A40: 46211 | B40: =IF(A40="","",IFERROR(INT((A40-C3)/7)+I4,"")) -> 48 | C40: 9859 | D40: 794 | E40: 1 | F40: 1 | G40: =IF(A40="","",IFERROR(SUM(E$7:E40)/C4*100,"")) -> 1.3620556 | H40: 6382 | I40: 6239 | J40: =IF(OR(A40="",H40="",H40=0),"",I40/H40*100) -> 97.759323 | K40: =IF(OR(A40="",C40="",C40=0),"",H40/C40*100) -> 64.732732 | L40: 64.7 | M40: 1587 | N40: 84 | O40: =IF(OR(A40="",C40="",C40=0),"",M40/C40*1000) -> 160.96967 | P40: =IF(OR(A40="",D40="",D40=0),"",N40/D40*1000) -> 105.79345 | Q40: 3008 | R40: =IF(OR(A40="",M40="",M40+N40=0),"",Q40/(M40+N40)) -> 1.8001197 | W40: Woxsol 2kg / 50 l wody
A41: 46304 | B41: =IF(A41="","",IFERROR(INT((A41-C3)/7)+I4,"")) -> 62 | C41: 9857 | D41: 793 | E41: 2 | F41: 0 | G41: =IF(A41="","",IFERROR(SUM(E$7:E41)/C4*100,"")) -> 1.3813756 | H41: 6409 | I41: 6260 | J41: =IF(OR(A41="",H41="",H41=0),"",I41/H41*100) -> 97.675144 | K41: =IF(OR(A41="",C41="",C41=0),"",H41/C41*100) -> 65.019783 | L41: 65 | M41: 1587 | N41: 84 | O41: =IF(OR(A41="",C41="",C41=0),"",M41/C41*1000) -> 161.00233 | P41: =IF(OR(A41="",D41="",D41=0),"",N41/D41*1000) -> 105.92686 | Q41: 3294 | R41: =IF(OR(A41="",M41="",M41+N41=0),"",Q41/(M41+N41)) -> 1.9712747 | U41: 4274 | V41: 4551 | W41: Woxsol 2kg / 50 l wody
...

Sheet Dzienne 3
A1: Nazwa stada: | C1: Ferma za Lakiem K3
A2: Linia genetyczna: | C2: Ross 308
A3: Data wstawienia: | C3: 45870
A4: Kury wstawione: | C4: 10352 | E4: Koguty wstawione: | G4: 1101 | H4: Wiek wstaw. (tyg): | I4: 0
A6: Data | B6: Tyg.życia | C6: Kury żywe | D6: Koguty żywe | E6: Upadki kury | F6: Upadki koguty | G6: Upadki %kum. | H6: Jaja ogółem | I6: Jaja wylęg. | J6: % jaj wylęg. | K6: % nieśności | L6: Waga jaja(g) | M6: Pasza kury(kg) | N6: Pasza kog.(kg) | O6: Dawka kura(g) | P6: Dawka kog.(g) | Q6: Woda(l) | R6: Woda:Pasza | S6: Temp.kurnik°C | T6: Temp.magaz.jaj°C | U6: Waga kury(g) | V6: Waga kog.(g) | W6: Suplement./Leczenie | X6: Notatki wet.
A7: 46178 | B7: =IF(A7="","",IFERROR(INT((A7-C3)/7)+I4,"")) -> 44 | C7: 10153 | D7: 753 | E7: 1 | F7: 1 | G7: =IF(A7="","",IFERROR(SUM(E$7:E7)/C4*100,"")) -> 0.0096599691 | H7: 7496 | I7: 7323 | J7: =IF(OR(A7="",H7="",H7=0),"",I7/H7*100) -> 97.692102 | K7: =IF(OR(A7="",C7="",C7=0),"",H7/C7*100) -> 73.830395 | L7: 65 | M7: 1675 | N7: 71 | O7: =IF(OR(A7="",C7="",C7=0),"",M7/C7*1000) -> 164.97587 | P7: =IF(OR(A7="",D7="",D7=0),"",N7/D7*1000) -> 94.289509 | Q7: 3582 | R7: =IF(OR(A7="",M7="",M7+N7=0),"",Q7/(M7+N7)) -> 2.0515464
A8: 46179 | B8: =IF(A8="","",IFERROR(INT((A8-C3)/7)+I4,"")) -> 44 | C8: 10147 | D8: 748 | E8: 6 | F8: 5 | G8: =IF(A8="","",IFERROR(SUM(E$7:E8)/C4*100,"")) -> 0.067619784 | H8: 7579 | I8: 7391 | J8: =IF(OR(A8="",H8="",H8=0),"",I8/H8*100) -> 97.519462 | K8: =IF(OR(A8="",C8="",C8=0),"",H8/C8*100) -> 74.692027 | L8: 65.2 | M8: 1675 | N8: 71 | O8: =IF(OR(A8="",C8="",C8=0),"",M8/C8*1000) -> 165.07342 | P8: =IF(OR(A8="",D8="",D8=0),"",N8/D8*1000) -> 94.919786 | Q8: 3497 | R8: =IF(OR(A8="",M8="",M8+N8=0),"",Q8/(M8+N8)) -> 2.0028637
A9: 46180 | B9: =IF(A9="","",IFERROR(INT((A9-C3)/7)+I4,"")) -> 44 | C9: 10146 | D9: 748 | E9: 1 | G9: =IF(A9="","",IFERROR(SUM(E$7:E9)/C4*100,"")) -> 0.077279753 | H9: 7471 | I9: 7307 | J9: =IF(OR(A9="",H9="",H9=0),"",I9/H9*100) -> 97.804845 | K9: =IF(OR(A9="",C9="",C9=0),"",H9/C9*100) -> 73.63493 | L9: 65.1 | M9: 1674 | N9: 71 | O9: =IF(OR(A9="",C9="",C9=0),"",M9/C9*1000) -> 164.99113 | P9: =IF(OR(A9="",D9="",D9=0),"",N9/D9*1000) -> 94.919786 | Q9: 3460 | R9: =IF(OR(A9="",M9="",M9+N9=0),"",Q9/(M9+N9)) -> 1.982808
A10: 46181 | B10: =IF(A10="","",IFERROR(INT((A10-C3)/7)+I4,"")) -> 44 | C10: 10140 | D10: 746 | E10: 6 | F10: 2 | G10: =IF(A10="","",IFERROR(SUM(E$7:E10)/C4*100,"")) -> 0.13523957 | H10: 7589 | I10: 7373 | J10: =IF(OR(A10="",H10="",H10=0),"",I10/H10*100) -> 97.153775 | K10: =IF(OR(A10="",C10="",C10=0),"",H10/C10*100) -> 74.842209 | L10: 65.1 | M10: 1673 | N10: 71 | O10: =IF(OR(A10="",C10="",C10=0),"",M10/C10*1000) -> 164.99014 | P10: =IF(OR(A10="",D10="",D10=0),"",N10/D10*1000) -> 95.174263 | Q10: 3524 | R10: =IF(OR(A10="",M10="",M10+N10=0),"",Q10/(M10+N10)) -> 2.0206422
A11: 46182 | B11: =IF(A11="","",IFERROR(INT((A11-C3)/7)+I4,"")) -> 44 | C11: 10137 | D11: 745 | E11: 3 | F11: 1 | G11: =IF(A11="","",IFERROR(SUM(E$7:E11)/C4*100,"")) -> 0.16421947 | H11: 7421 | I11: 7222 | J11: =IF(OR(A11="",H11="",H11=0),"",I11/H11*100) -> 97.318421 | K11: =IF(OR(A11="",C11="",C11=0),"",H11/C11*100) -> 73.207063 | L11: 65.3 | M11: 1673 | N11: 71 | O11: =IF(OR(A11="",C11="",C11=0),"",M11/C11*1000) -> 165.03897 | P11: =IF(OR(A11="",D11="",D11=0),"",N11/D11*1000) -> 95.302013 | Q11: 3776 | R11: =IF(OR(A11="",M11="",M11+N11=0),"",Q11/(M11+N11)) -> 2.1651376
A12: 46183 | B12: =IF(A12="","",IFERROR(INT((A12-C3)/7)+I4,"")) -> 44 | C12: 10136 | D12: 744 | E12: 1 | F12: 1 | G12: =IF(A12="","",IFERROR(SUM(E$7:E12)/C4*100,"")) -> 0.17387944 | H12: 7459 | I12: 7253 | J12: =IF(OR(A12="",H12="",H12=0),"",I12/H12*100) -> 97.238236 | K12: =IF(OR(A12="",C12="",C12=0),"",H12/C12*100) -> 73.589187 | L12: 65.5 | M12: 1673 | N12: 71 | O12: =IF(OR(A12="",C12="",C12=0),"",M12/C12*1000) -> 165.05525 | P12: =IF(OR(A12="",D12="",D12=0),"",N12/D12*1000) -> 95.430108 | Q12: 3566 | R12: =IF(OR(A12="",M12="",M12+N12=0),"",Q12/(M12+N12)) -> 2.0447248 | X12: Avihepasilimerin 2l (W CIĄGŁYM PICIU DAWKA NA 1000LITRÓW WODY)
A13: 46184 | B13: =IF(A13="","",IFERROR(INT((A13-C3)/7)+I4,"")) -> 44 | C13: 10132 | D13: 742 | E13: 4 | F13: 2 | G13: =IF(A13="","",IFERROR(SUM(E$7:E13)/C4*100,"")) -> 0.21251932 | H13: 7384 | I13: 7238 | J13: =IF(OR(A13="",H13="",H13=0),"",I13/H13*100) -> 98.022752 | K13: =IF(OR(A13="",C13="",C13=0),"",H13/C13*100) -> 72.87801 | L13: 65.6 | M13: 1673 | N13: 71 | O13: =IF(OR(A13="",C13="",C13=0),"",M13/C13*1000) -> 165.12041 | P13: =IF(OR(A13="",D13="",D13=0),"",N13/D13*1000) -> 95.687332 | Q13: 3270 | R13: =IF(OR(A13="",M13="",M13+N13=0),"",Q13/(M13+N13)) -> 1.875 | U13: 4084 | V13: 4391 | X13: Avihepasilimerin 2l (W CIĄGŁYM PICIU DAWKA NA 1000LITRÓW WODY)
A14: 46185 | B14: =IF(A14="","",IFERROR(INT((A14-C3)/7)+I4,"")) -> 45 | C14: 10131 | D14: 741 | E14: 1 | F14: 1 | G14: =IF(A14="","",IFERROR(SUM(E$7:E14)/C4*100,"")) -> 0.22217929 | H14: 7433 | I14: 7283 | J14: =IF(OR(A14="",H14="",H14=0),"",I14/H14*100) -> 97.981972 | K14: =IF(OR(A14="",C14="",C14=0),"",H14/C14*100) -> 73.368868 | L14: 65.5 | M14: 1672 | N14: 76 | O14: =IF(OR(A14="",C14="",C14=0),"",M14/C14*1000) -> 165.038 | P14: =IF(OR(A14="",D14="",D14=0),"",N14/D14*1000) -> 102.5641 | Q14: 3442 | R14: =IF(OR(A14="",M14="",M14+N14=0),"",Q14/(M14+N14)) -> 1.9691076 | X14: Avihepasilimerin 2l (W CIĄGŁYM PICIU DAWKA NA 1000LITRÓW WODY)
A15: 46186 | B15: =IF(A15="","",IFERROR(INT((A15-C3)/7)+I4,"")) -> 45 | C15: 10131 | D15: 740 | F15: 1 | G15: =IF(A15="","",IFERROR(SUM(E$7:E15)/C4*100,"")) -> 0.22217929 | H15: 7321 | I15: 7149 | J15: =IF(OR(A15="",H15="",H15=0),"",I15/H15*100) -> 97.650594 | K15: =IF(OR(A15="",C15="",C15=0),"",H15/C15*100) -> 72.26335 | L15: 65.6 | M15: 1672 | N15: 76 | O15: =IF(OR(A15="",C15="",C15=0),"",M15/C15*1000) -> 165.038 | P15: =IF(OR(A15="",D15="",D15=0),"",N15/D15*1000) -> 102.7027 | Q15: 3341 | R15: =IF(OR(A15="",M15="",M15+N15=0),"",Q15/(M15+N15)) -> 1.9113272 | X15: Avihepasilimerin 2l (W CIĄGŁYM PICIU DAWKA NA 1000LITRÓW WODY)
A16: 46187 | B16: =IF(A16="","",IFERROR(INT((A16-C3)/7)+I4,"")) -> 45 | C16: 10130 | D16: 738 | E16: 1 | F16: 2 | G16: =IF(A16="","",IFERROR(SUM(E$7:E16)/C4*100,"")) -> 0.23183926 | H16: 7399 | I16: 7223 | J16: =IF(OR(A16="",H16="",H16=0),"",I16/H16*100) -> 97.6213 | K16: =IF(OR(A16="",C16="",C16=0),"",H16/C16*100) -> 73.040474 | L16: 65.5 | M16: 1672 | N16: 76 | O16: =IF(OR(A16="",C16="",C16=0),"",M16/C16*1000) -> 165.05429 | P16: =IF(OR(A16="",D16="",D16=0),"",N16/D16*1000) -> 102.98103 | Q16: 3383 | R16: =IF(OR(A16="",M16="",M16+N16=0),"",Q16/(M16+N16)) -> 1.9353547 | X16: Avihepasilimerin 2l (W CIĄGŁYM PICIU DAWKA NA 1000LITRÓW WODY)
A17: 46188 | B17: =IF(A17="","",IFERROR(INT((A17-C3)/7)+I4,"")) -> 45 | C17: 10127 | D17: 736 | E17: 3 | F17: 2 | G17: =IF(A17="","",IFERROR(SUM(E$7:E17)/C4*100,"")) -> 0.26081917 | H17: 7420 | I17: 7235 | J17: =IF(OR(A17="",H17="",H17=0),"",I17/H17*100) -> 97.506739 | K17: =IF(OR(A17="",C17="",C17=0),"",H17/C17*100) -> 73.269478 | L17: 65.5 | M17: 1672 | N17: 76 | O17: =IF(OR(A17="",C17="",C17=0),"",M17/C17*1000) -> 165.10319 | P17: =IF(OR(A17="",D17="",D17=0),"",N17/D17*1000) -> 103.26087 | Q17: 3631 | R17: =IF(OR(A17="",M17="",M17+N17=0),"",Q17/(M17+N17)) -> 2.0772311
A18: 46189 | B18: =IF(A18="","",IFERROR(INT((A18-C3)/7)+I4,"")) -> 45 | C18: 10122 | D18: 735 | E18: 5 | F18: 1 | G18: =IF(A18="","",IFERROR(SUM(E$7:E18)/C4*100,"")) -> 0.30911901 | H18: 7410 | I18: 7245 | J18: =IF(OR(A18="",H18="",H18=0),"",I18/H18*100) -> 97.773279 | K18: =IF(OR(A18="",C18="",C18=0),"",H18/C18*100) -> 73.206876 | L18: 65.5 | M18: 1672 | N18: 76 | O18: =IF(OR(A18="",C18="",C18=0),"",M18/C18*1000) -> 165.18475 | P18: =IF(OR(A18="",D18="",D18=0),"",N18/D18*1000) -> 103.40136 | Q18: 3395 | R18: =IF(OR(A18="",M18="",M18+N18=0),"",Q18/(M18+N18)) -> 1.9422197
A19: 46190 | B19: =IF(A19="","",IFERROR(INT((A19-C3)/7)+I4,"")) -> 45 | C19: 10120 | D19: 735 | E19: 2 | G19: =IF(A19="","",IFERROR(SUM(E$7:E19)/C4*100,"")) -> 0.32843895 | H19: 7351 | I19: 7151 | J19: =IF(OR(A19="",H19="",H19=0),"",I19/H19*100) -> 97.279282 | K19: =IF(OR(A19="",C19="",C19=0),"",H19/C19*100) -> 72.63834 | L19: 65.4 | M19: 1672 | N19: 76 | O19: =IF(OR(A19="",C19="",C19=0),"",M19/C19*1000) -> 165.21739 | P19: =IF(OR(A19="",D19="",D19=0),"",N19/D19*1000) -> 103.40136 | Q19: 3504 | R19: =IF(OR(A19="",M19="",M19+N19=0),"",Q19/(M19+N19)) -> 2.0045767
A20: 46191 | B20: =IF(A20="","",IFERROR(INT((A20-C3)/7)+I4,"")) -> 45 | C20: 10117 | D20: 734 | E20: 3 | F20: 1 | G20: =IF(A20="","",IFERROR(SUM(E$7:E20)/C4*100,"")) -> 0.35741886 | H20: 7347 | I20: 7186 | J20: =IF(OR(A20="",H20="",H20=0),"",I20/H20*100) -> 97.808629 | K20: =IF(OR(A20="",C20="",C20=0),"",H20/C20*100) -> 72.620342 | L20: 65.6 | M20: 1672 | N20: 76 | O20: =IF(OR(A20="",C20="",C20=0),"",M20/C20*1000) -> 165.26638 | P20: =IF(OR(A20="",D20="",D20=0),"",N20/D20*1000) -> 103.54223 | Q20: 3566 | R20: =IF(OR(A20="",M20="",M20+N20=0),"",Q20/(M20+N20)) -> 2.0400458 | U20: 4169 | V20: 4568
A21: 46192 | B21: =IF(A21="","",IFERROR(INT((A21-C3)/7)+I4,"")) -> 46 | C21: 10115 | D21: 734 | E21: 2 | G21: =IF(A21="","",IFERROR(SUM(E$7:E21)/C4*100,"")) -> 0.37673879 | H21: 7255 | I21: 7089 | J21: =IF(OR(A21="",H21="",H21=0),"",I21/H21*100) -> 97.711923 | K21: =IF(OR(A21="",C21="",C21=0),"",H21/C21*100) -> 71.725161 | L21: 65.7 | M21: 1659 | N21: 74 | O21: =IF(OR(A21="",C21="",C21=0),"",M21/C21*1000) -> 164.01384 | P21: =IF(OR(A21="",D21="",D21=0),"",N21/D21*1000) -> 100.81744 | Q21: 3710 | R21: =IF(OR(A21="",M21="",M21+N21=0),"",Q21/(M21+N21)) -> 2.1407963
A22: 46193 | B22: =IF(A22="","",IFERROR(INT((A22-C3)/7)+I4,"")) -> 46 | C22: 10112 | D22: 733 | E22: 3 | F22: 1 | G22: =IF(A22="","",IFERROR(SUM(E$7:E22)/C4*100,"")) -> 0.4057187 | H22: 7269 | I22: 7089 | J22: =IF(OR(A22="",H22="",H22=0),"",I22/H22*100) -> 97.523731 | K22: =IF(OR(A22="",C22="",C22=0),"",H22/C22*100) -> 71.884889 | L22: 65.7 | M22: 1659 | N22: 74 | O22: =IF(OR(A22="",C22="",C22=0),"",M22/C22*1000) -> 164.0625 | P22: =IF(OR(A22="",D22="",D22=0),"",N22/D22*1000) -> 100.95498 | Q22: 3945 | R22: =IF(OR(A22="",M22="",M22+N22=0),"",Q22/(M22+N22)) -> 2.2763993
A23: 46194 | B23: =IF(A23="","",IFERROR(INT((A23-C3)/7)+I4,"")) -> 46 | C23: 10111 | D23: 732 | E23: 1 | F23: 1 | G23: =IF(A23="","",IFERROR(SUM(E$7:E23)/C4*100,"")) -> 0.41537867 | H23: 7293 | I23: 7142 | J23: =IF(OR(A23="",H23="",H23=0),"",I23/H23*100) -> 97.929521 | K23: =IF(OR(A23="",C23="",C23=0),"",H23/C23*100) -> 72.129364 | L23: 65.7 | M23: 1659 | N23: 74 | O23: =IF(OR(A23="",C23="",C23=0),"",M23/C23*1000) -> 164.07873 | P23: =IF(OR(A23="",D23="",D23=0),"",N23/D23*1000) -> 101.0929 | Q23: 3606 | R23: =IF(OR(A23="",M23="",M23+N23=0),"",Q23/(M23+N23)) -> 2.0807848
A24: 46195 | B24: =IF(A24="","",IFERROR(INT((A24-C3)/7)+I4,"")) -> 46 | C24: =C23-E24 -> 10110 | D24: =D23-F23 -> 731 | E24: 1 | F24: 1 | G24: =IF(A24="","",IFERROR(SUM(E$7:E24)/C4*100,"")) -> 0.42503864 | H24: 7137 | I24: 6961 | J24: =IF(OR(A24="",H24="",H24=0),"",I24/H24*100) -> 97.533978 | K24: =IF(OR(A24="",C24="",C24=0),"",H24/C24*100) -> 70.593472 | L24: 65.7 | M24: 1659 | N24: 74 | O24: =IF(OR(A24="",C24="",C24=0),"",M24/C24*1000) -> 164.09496 | P24: =IF(OR(A24="",D24="",D24=0),"",N24/D24*1000) -> 101.23119 | Q24: 3548 | R24: =IF(OR(A24="",M24="",M24+N24=0),"",Q24/(M24+N24)) -> 2.0473168
A25: 46196 | B25: =IF(A25="","",IFERROR(INT((A25-C3)/7)+I4,"")) -> 46 | C25: =C24-E25 -> 10109 | D25: =D24-F24 -> 730 | E25: 1 | G25: =IF(A25="","",IFERROR(SUM(E$7:E25)/C4*100,"")) -> 0.43469861 | H25: 7151 | I25: 6979 | J25: =IF(OR(A25="",H25="",H25=0),"",I25/H25*100) -> 97.594742 | K25: =IF(OR(A25="",C25="",C25=0),"",H25/C25*100) -> 70.738945 | L25: 65.8 | M25: 1659 | N25: 74 | O25: =IF(OR(A25="",C25="",C25=0),"",M25/C25*1000) -> 164.11119 | P25: =IF(OR(A25="",D25="",D25=0),"",N25/D25*1000) -> 101.36986 | Q25: 3455 | R25: =IF(OR(A25="",M25="",M25+N25=0),"",Q25/(M25+N25)) -> 1.9936526
A26: 46197 | B26: =IF(A26="","",IFERROR(INT((A26-C3)/7)+I4,"")) -> 46 | C26: =C25-E26 -> 10106 | D26: =D25-F25 -> 730 | E26: 3 | G26: =IF(A26="","",IFERROR(SUM(E$7:E26)/C4*100,"")) -> 0.46367852 | H26: 7174 | I26: 6988 | J26: =IF(OR(A26="",H26="",H26=0),"",I26/H26*100) -> 97.407304 | K26: =IF(OR(A26="",C26="",C26=0),"",H26/C26*100) -> 70.987532 | L26: 65.9 | M26: 1659 | N26: 74 | O26: =IF(OR(A26="",C26="",C26=0),"",M26/C26*1000) -> 164.15991 | P26: =IF(OR(A26="",D26="",D26=0),"",N26/D26*1000) -> 101.36986 | Q26: 3629 | R26: =IF(OR(A26="",M26="",M26+N26=0),"",Q26/(M26+N26)) -> 2.0940565
A27: 46198 | B27: =IF(A27="","",IFERROR(INT((A27-C3)/7)+I4,"")) -> 46 | C27: =C26-E27 -> 10105 | D27: =D26-F26 -> 730 | E27: 1 | G27: =IF(A27="","",IFERROR(SUM(E$7:E27)/C4*100,"")) -> 0.47333849 | H27: 7186 | I27: 7010 | J27: =IF(OR(A27="",H27="",H27=0),"",I27/H27*100) -> 97.550793 | K27: =IF(OR(A27="",C27="",C27=0),"",H27/C27*100) -> 71.11331 | L27: 65.9 | M27: 1659 | N27: 74 | O27: =IF(OR(A27="",C27="",C27=0),"",M27/C27*1000) -> 164.17615 | P27: =IF(OR(A27="",D27="",D27=0),"",N27/D27*1000) -> 101.36986 | Q27: 3895 | R27: =IF(OR(A27="",M27="",M27+N27=0),"",Q27/(M27+N27)) -> 2.2475476 | U27: 4180 | V27: 4669
